Workbook

Sheet INSTRUCTIONS
B2: PLANWISE HAUS | D2: PLANWISE HAUS · INSTRUCTIONS
D3: EXCEL TEMPLATES FOR LIFE & HOME
B5: OVERVIEW | D5: WELCOME TO YOUR PLANWISE HAUS ANNUAL BUDGET
B6: INSTRUCTIONS | D6: Thank you for your purchase! This spreadsheet is your complete annual financial command center.
B7: SETUP
B8: DASHBOARD | D8: GETTING STARTED — FOLLOW THESE STEPS
D9: Step 1 | E9: Go to SETUP tab → enter your name, year, and preferred currency.
B10: ACCOUNTS | D10: Step 2 | E10: Add your bank accounts in BANK ACCOUNTS.
B11: BANK ACCOUNTS | D11: Step 3 | E11: Enter fixed monthly bills in RECURRING TRANSACTIONS.
B12: RECURRING | D12: Step 4 | E12: Log daily spending in VARIABLE TRANSACTIONS.
B13: PAYMENTS | D13: Step 5 | E13: Enter your income and monthly budget actuals in each monthly tab (JAN–DEC).
B14: VARIABLE | D14: Step 6 | E14: View DASHBOARD for a full financial overview with charts.
D15: Step 7 | E15: Use DEBT CALC and INVEST FORECAST for long-term planning.
B16: ANALYTICS
B17: ANNUAL TOTALS | D17: COLOR LEGEND
B18: PAYCHECK | E18: Primary Teal-Green — Titles, navigation, key labels
B19: CALENDAR | E19: Secondary Teal — Section headers, active nav state
E20: Gold Accent — Input fields, KPI highlights
B21: MONTHLY | E21: Success Green — On-budget, surplus, positive values
B22: JANUARY | E22: Alert Red — Over-budget, deficit, warnings
B23: FEBRUARY
B24: MARCH | D24: TIPS
B25: APRIL | D25: • Yellow-highlighted cells are INPUT fields — that is where you enter your data.
B26: MAY | D26: • Do not delete rows in monthly tabs — formulas are row-dependent.
B27: JUNE | D27: • The Dashboard updates automatically as you fill in monthly data.
B28: JULY | D28: • Use the left sidebar on every tab to navigate instantly.
B29: AUGUST | D29: • The 50/30/20 Dashboard calculates automatically from your Setup budget.
B30: SEPTEMBER
B31: OCTOBER
B32: NOVEMBER
B33: DECEMBER
B35: TOOLS
B36: 50-30-20
B37: EXPENSE DIST
B38: SINKING FUNDS
B39: DEBT CALC
B40: NET WORTH
B41: INVEST FORECAST
B42: NO-SPEND

Sheet SETUP
B2: PLANWISE HAUS | D2: PLANWISE HAUS · SETUP
D3: EXCEL TEMPLATES FOR LIFE & HOME
B5: OVERVIEW | D5: YOUR INFORMATION
B6: INSTRUCTIONS | D6: Your Name | G6: Jane Smith
B7: SETUP | D7: Budget Year | G7: 2025
B8: DASHBOARD | D8: Currency Symbol | G8: $
D9: Annual Income Goal | G9: 75000
B10: ACCOUNTS | D10: Annual Savings Goal | G10: 15000
B11: BANK ACCOUNTS | D11: Emergency Fund Goal | G11: 10000
B12: RECURRING
B13: PAYMENTS
B14: VARIABLE | D14: EXPENSE CATEGORIES & MONTHLY BUDGETS (edit to customize)
D15: Category | E15: Type | F15: Monthly Budget | G15: Annual Budget
B16: ANALYTICS | D16: Housing | E16: Need | F16: 1500 | G16: =F16*12
B17: ANNUAL TOTALS | D17: Transportation | E17: Need | F17: 400 | G17: =F17*12
B18: PAYCHECK | D18: Food & Dining | E18: Need | F18: 600 | G18: =F18*12
B19: CALENDAR | D19: Utilities | E19: Need | F19: 200 | G19: =F19*12
D20: Healthcare | E20: Need | F20: 150 | G20: =F20*12
B21: MONTHLY | D21: Insurance | E21: Need | F21: 250 | G21: =F21*12
B22: JANUARY | D22: Entertainment | E22: Want | F22: 150 | G22: =F22*12
B23: FEBRUARY | D23: Shopping | E23: Want | F23: 200 | G23: =F23*12
B24: MARCH | D24: Personal Care | E24: Want | F24: 100 | G24: =F24*12
B25: APRIL | D25: Education | E25: Want | F25: 50 | G25: =F25*12
B26: MAY | D26: Savings | E26: Savings | F26: 500 | G26: =F26*12
B27: JUNE | D27: Investments | E27: Savings | F27: 300 | G27: =F27*12
B28: JULY | D28: Debt Payments | E28: Need | F28: 200 | G28: =F28*12
B29: AUGUST | D29: Gifts & Donations | E29: Want | F29: 100 | G29: =F29*12
B30: SEPTEMBER | D30: Other | E30: Other | F30: 100 | G30: =F30*12
B31: OCTOBER | D31: MONTHLY TOTAL | F31: =SUM(F16:F30) | G31: =SUM(G16:G30)
B32: NOVEMBER
B33: DECEMBER
B35: TOOLS
B36: 50-30-20
B37: EXPENSE DIST
B38: SINKING FUNDS
B39: DEBT CALC
B40: NET WORTH
B41: INVEST FORECAST
B42: NO-SPEND

Sheet BANK ACCOUNTS
B2: PLANWISE HAUS | D2: PLANWISE HAUS · BANK ACCOUNTS
D3: EXCEL TEMPLATES FOR LIFE & HOME
B5: OVERVIEW | D5: BANK ACCOUNTS & BALANCES
B6: INSTRUCTIONS | D6: Account Name | E6: Bank / Institution | F6: Account Type | G6: Opening Balance | H6: Current Balance | I6: Change | J6: Notes
B7: SETUP | D7: Primary Checking | E7: Chase Bank | F7: Checking | G7: 3500 | H7: 4250 | I7: =F7-E7
B8: DASHBOARD | D8: Emergency Savings | E8: Ally Bank | F8: Savings | G8: 10000 | H8: 10500 | I8: =F8-E8
D9: Investment Account | E9: Fidelity | F9: Investment | G9: 25000 | H9: 26800 | I9: =F9-E9
B10: ACCOUNTS | D10: Credit Card | E10: Capital One | F10: Credit Card | G10: -1200 | H10: -950 | I10: =F10-E10
B11: BANK ACCOUNTS | D11: Joint Account | E11: Credit Union | F11: Checking | G11: 2000 | H11: 2350 | I11: =F11-E11
B12: RECURRING
B13: PAYMENTS
B14: VARIABLE | D14: SUMMARY
D15: Total Assets | G15: =SUMIF(F7:F60,"Checking",E7:E60)+SUMIF(F7:F60,"Savings",E7:E60)+SUMIF(F7:F60,"Investment",E7:E60)
B16: ANALYTICS | D16: Total Liabilities | G16: =SUMIF(F7:F60,"Credit Card",E7:E60)+SUMIF(F7:F60,"Loan",E7:E60)
B17: ANNUAL TOTALS | D17: Net Worth | G17: =E15+E16
B18: PAYCHECK
B19: CALENDAR
B21: MONTHLY
B22: JANUARY
B23: FEBRUARY
B24: MARCH
B25: APRIL
B26: MAY
B27: JUNE
B28: JULY
B29: AUGUST
B30: SEPTEMBER
... B42: NO-SPEND

Sheet RECURRING
B2: PLANWISE HAUS | D2: PLANWISE HAUS · RECURRING TRANSACTIONS
D3: EXCEL TEMPLATES FOR LIFE & HOME
B5: OVERVIEW | D5: FIXED / RECURRING MONTHLY EXPENSES
B6: INSTRUCTIONS | D6: Description | E6: Category | F6: Monthly Amount | G6: Annual Total | H6: Due Day | I6: Payment Method | J6: Active?
B7: SETUP | D7: Rent / Mortgage | E7: Housing | F7: 1500 | G7: =F7*12 | H7: 1 | I7: Auto-Pay | J7: Yes
B8: DASHBOARD | D8: Car Payment | E8: Transportation | F8: 385 | G8: =F8*12 | H8: 15 | I8: Auto-Pay | J8: Yes
D9: Car Insurance | E9: Insurance | F9: 145 | G9: =F9*12 | H9: 1 | I9: Auto-Pay | J9: Yes
B10: ACCOUNTS | D10: Health Insurance | E10: Healthcare | F10: 220 | G10: =F10*12 | H10: 1 | I10: Auto-Pay | J10: Yes
B11: BANK ACCOUNTS | D11: Electric | E11: Utilities | F11: 120 | G11: =F11*12 | H11: 10 | I11: Auto-Pay | J11: Yes
B12: RECURRING | D12: Internet | E12: Utilities | F12: 65 | G12: =F12*12 | H12: 20 | I12: Auto-Pay | J12: Yes
B13: PAYMENTS | D13: Phone Bill | E13: Utilities | F13: 80 | G13: =F13*12 | H13: 25 | I13: Auto-Pay | J13: Yes
B14: VARIABLE | D14: Netflix | E14: Entertainment | F14: 15.99 | G14: =F14*12 | H14: 7 | I14: Credit Card | J14: Yes
D15: Spotify | E15: Entertainment | F15: 9.99 | G15: =F15*12 | H15: 14 | I15: Credit Card | J15: Yes
B16: ANALYTICS | D16: Gym Membership | E16: Personal Care | F16: 45 | G16: =F16*12 | H16: 1 | I16: Debit Card | J16: Yes
B17: ANNUAL TOTALS
B18: PAYCHECK | D18: MONTHLY TOTAL | F18: =SUMIF(J7:J17,"Yes",F7:F17) | G18: =F18*12
B19: CALENDAR
B21: MONTHLY
B22: JANUARY
B23: FEBRUARY
B24: MARCH
B25: APRIL
B26: MAY
B27: JUNE
B28: JULY
B29: AUGUST
B30: SEPTEMBER
B31: OCTOBER
... B42: NO-SPEND

Sheet PAYMENTS
B2: PLANWISE HAUS | D2: PLANWISE HAUS · BILL PAYMENT TRACKER
D3: EXCEL TEMPLATES FOR LIFE & HOME
B5: OVERVIEW | D5: MONTHLY BILL PAYMENT TRACKER
B6: INSTRUCTIONS | D6: Bill / Description | E6: Category | F6: Amount Due | G6: Due Date | H6: Date Paid | I6: Status | J6: Payment Method
B7: SETUP | D7: Rent / Mortgage | E7: Housing | F7: 1500 | G7: 1 | I7: Pending | J7: Auto-Pay
B8: DASHBOARD | D8: Car Payment | E8: Transportation | F8: 385 | G8: 15 | I8: Pending | J8: Auto-Pay
D9: Electric | E9: Utilities | F9: 120 | G9: 10 | I9: Pending | J9: Auto-Pay
B10: ACCOUNTS | D10: Internet | E10: Utilities | F10: 65 | G10: 20 | I10: Pending | J10: Auto-Pay
B11: BANK ACCOUNTS | D11: Phone | E11: Utilities | F11: 80 | G11: 25 | I11: Pending | J11: Auto-Pay
B12: RECURRING | D12: Health Insurance | E12: Healthcare | F12: 220 | G12: 1 | I12: Pending | J12: Auto-Pay
B13: PAYMENTS | D13: Car Insurance | E13: Insurance | F13: 145 | G13: 1 | I13: Pending | J13: Auto-Pay
B14: VARIABLE | D14: Gym | E14: Personal Care | F14: 45 | G14: 1 | I14: Pending | J14: Auto-Pay
D15: Netflix | E15: Entertainment | F15: 15.99 | G15: 7 | I15: Pending | J15: Auto-Pay
B16: ANALYTICS | D16: Spotify | E16: Entertainment | F16: 9.99 | G16: 14 | I16: Pending | J16: Auto-Pay
B17: ANNUAL TOTALS | D17: Student Loan | E17: Debt Payments | F17: 250 | G17: 20 | I17: Pending | J17: Auto-Pay
B18: PAYCHECK | D18: Credit Card Min | E18: Debt Payments | F18: 100 | G18: 28 | I18: Pending | J18: Auto-Pay
B19: CALENDAR
D20: TOTAL DUE | F20: =SUM(F7:F19)
B21: MONTHLY | D21: TOTAL PAID | F21: =SUMIF(J7:J19,"Paid",F7:F19)
B22: JANUARY
B23: FEBRUARY
B24: MARCH
B25: APRIL
B26: MAY
B27: JUNE
B28: JULY
B29: AUGUST
B30: SEPTEMBER
B31: OCTOBER
B32: NOVEMBER
B33: DECEMBER
... B42: NO-SPEND

Sheet VARIABLE
B2: PLANWISE HAUS | D2: PLANWISE HAUS · VARIABLE TRANSACTIONS
D3: EXCEL TEMPLATES FOR LIFE & HOME
B5: OVERVIEW | D5: DAILY / VARIABLE TRANSACTION LOG
B6: INSTRUCTIONS | D6: Date | E6: Description | F6: Category | G6: Amount | H6: Payment Method | I6: Tax Deductible? | J6: Notes
B7: SETUP | D7: 01/03/2025 | E7: Grocery Store | F7: Food & Dining | G7: 87.43 | H7: Debit Card | I7: No
B8: DASHBOARD | D8: 01/05/2025 | E8: Gas Station | F8: Transportation | G8: 52.1 | H8: Credit Card | I8: No
D9: 01/07/2025 | E9: Restaurant | F9: Food & Dining | G9: 65 | H9: Credit Card | I9: No | J9: Anniversary
B10: ACCOUNTS | D10: 01/10/2025 | E10: Amazon | F10: Shopping | G10: 34.99 | H10: Credit Card | I10: No
B11: BANK ACCOUNTS | D11: 01/12/2025 | E11: Doctor Co-pay | F11: Healthcare | G11: 30 | H11: Debit Card | I11: Yes
B12: RECURRING
B13: PAYMENTS
B14: VARIABLE
B16: ANALYTICS
B17: ANNUAL TOTALS
B18: PAYCHECK
B19: CALENDAR
B21: MONTHLY
B22: JANUARY
B23: FEBRUARY
B24: MARCH
B25: APRIL
... B42: NO-SPEND

Sheet DASHBOARD
B2: PLANWISE HAUS | D2: PLANWISE HAUS · ALL-IN-ONE DASHBOARD
D3: EXCEL TEMPLATES FOR LIFE & HOME
B5: OVERVIEW | D5: FINANCIAL SNAPSHOT — 2025
B6: INSTRUCTIONS
B7: SETUP | D7: ='ANNUAL TOTALS'!E19 | I7: ='ANNUAL TOTALS'!F19 | N7: ='ANNUAL TOTALS'!G19
B8: DASHBOARD | D8: ANNUAL INCOME | I8: ANNUAL EXPENSES | N8: NET SAVINGS
B10: ACCOUNTS
B11: BANK ACCOUNTS
B12: RECURRING | D12: =IF('ANNUAL TOTALS'!E19>0,'ANNUAL TOTALS'!G19/'ANNUAL TOTALS'!E19,0) | I12: ='DEBT CALC'!E13 | N12: ='NET WORTH'!F28
B13: PAYMENTS | D13: SAVINGS RATE | I13: TOTAL DEBT | N13: NET WORTH
B14: VARIABLE
B16: ANALYTICS
B17: ANNUAL TOTALS | D17: INCOME vs. EXPENSES BY MONTH
B18: PAYCHECK
B19: CALENDAR
B21: MONTHLY
B22: JANUARY
B23: FEBRUARY
B24: MARCH
B25: APRIL
B26: MAY
B27: JUNE
B28: JULY
B29: AUGUST
B30: SEPTEMBER
... B32: NOVEMBER
B33: DECEMBER | D33: EXPENSE DISTRIBUTION
B35: TOOLS
B36: 50-30-20
B37: EXPENSE DIST
B38: SINKING FUNDS
B39: DEBT CALC
B40: NET WORTH
B41: INVEST FORECAST
B42: NO-SPEND
D50: MONTH-BY-MONTH SUMMARY
D51: Month | E51: Income | F51: Expenses | G51: Net Savings | H51: Savings Rate | I51: Status
D52: JANUARY | E52: ='ANNUAL TOTALS'!E7 | F52: ='ANNUAL TOTALS'!F7 | G52: ='ANNUAL TOTALS'!G7 | H52: ='ANNUAL TOTALS'!H7 | I52: =IF(G52>0,"Surplus","Deficit")
D53: FEBRUARY | E53: ='ANNUAL TOTALS'!E8 | F53: ='ANNUAL TOTALS'!F8 | G53: ='ANNUAL TOTALS'!G8 | H53: ='ANNUAL TOTALS'!H8 | I53: =IF(G53>0,"Surplus","Deficit")
D54: MARCH | E54: ='ANNUAL TOTALS'!E9 | F54: ='ANNUAL TOTALS'!F9 | G54: ='ANNUAL TOTALS'!G9 | H54: ='ANNUAL TOTALS'!H9 | I54: =IF(G54>0,"Surplus","Deficit")
...

Sheet ANNUAL TOTALS
B2: PLANWISE HAUS | D2: PLANWISE HAUS · ANNUAL TOTALS
D3: EXCEL TEMPLATES FOR LIFE & HOME
B5: OVERVIEW | D5: ANNUAL INCOME & EXPENSE SUMMARY
B6: INSTRUCTIONS | D6: Month | E6: Income (Actual) | F6: Expenses (Actual) | G6: Net Savings | H6: Savings Rate | I6: Running Total
B7: SETUP | D7: JANUARY | E7: ='JANUARY'!F11 | F7: ='JANUARY'!F30 | G7: =E7-F7 | H7: =IF(E7>0,G7/E7,0) | I7: =G7
B8: DASHBOARD | D8: FEBRUARY | E8: ='FEBRUARY'!F11 | F8: ='FEBRUARY'!F30 | G8: =E8-F8 | H8: =IF(E8>0,G8/E8,0) | I8: =H7+G8
D9: MARCH | E9: ='MARCH'!F11 | F9: ='MARCH'!F30 | G9: =E9-F9 | H9: =IF(E9>0,G9/E9,0) | I9: =H8+G9
B10: ACCOUNTS | D10: APRIL | E10: ='APRIL'!F11 | F10: ='APRIL'!F30 | G10: =E10-F10 | H10: =IF(E10>0,G10/E10,0) | I10: =H9+G10
B11: BANK ACCOUNTS | D11: MAY | E11: ='MAY'!F11 | F11: ='MAY'!F30 | G11: =E11-F11 | H11: =IF(E11>0,G11/E11,0) | I11: =H10+G11
B12: RECURRING | D12: JUNE | E12: ='JUNE'!F11 | F12: ='JUNE'!F30 | G12: =E12-F12 | H12: =IF(E12>0,G12/E12,0) | I12: =H11+G12
B13: PAYMENTS | D13: JULY | E13: ='JULY'!F11 | F13: ='JULY'!F30 | G13: =E13-F13 | H13: =IF(E13>0,G13/E13,0) | I13: =H12+G13
B14: VARIABLE | D14: AUGUST | E14: ='AUGUST'!F11 | F14: ='AUGUST'!F30 | G14: =E14-F14 | H14: =IF(E14>0,G14/E14,0) | I14: =H13+G14
D15: SEPTEMBER | E15: ='SEPTEMBER'!F11 | F15: ='SEPTEMBER'!F30 | G15: =E15-F15 | H15: =IF(E15>0,G15/E15,0) | I15: =H14+G15
B16: ANALYTICS | D16: OCTOBER | E16: ='OCTOBER'!F11 | F16: ='OCTOBER'!F30 | G16: =E16-F16 | H16: =IF(E16>0,G16/E16,0) | I16: =H15+G16
B17: ANNUAL TOTALS | D17: NOVEMBER | E17: ='NOVEMBER'!F11 | F17: ='NOVEMBER'!F30 | G17: =E17-F17 | H17: =IF(E17>0,G17/E17,0) | I17: =H16+G17
B18: PAYCHECK | D18: DECEMBER | E18: ='DECEMBER'!F11 | F18: ='DECEMBER'!F30 | G18: =E18-F18 | H18: =IF(E18>0,G18/E18,0) | I18: =H17+G18
B19: CALENDAR | D19: ANNUAL TOTAL | E19: =SUM(E7:E18) | F19: =SUM(F7:F18) | G19: =SUM(G7:G18)
B21: MONTHLY | D21: EXPENSE BY CATEGORY — ANNUAL
B22: JANUARY | D22: Category | E22: JAN | F22: FEB | G22: MAR | H22: APR | I22: MAY | J22: JUN | K22: JUL | L22: AUG | M22: SEP | N22: OCT | O22: NOV | P22: DEC | Q22: ANNUAL TOTAL
B23: FEBRUARY | D23: Housing | E23: ='JANUARY'!F15 | F23: ='FEBRUARY'!F15 | G23: ='MARCH'!F15 | H23: ='APRIL'!F15 | I23: ='MAY'!F15 | J23: ='JUNE'!F15 | K23: ='JULY'!F15 | L23: ='AUGUST'!F15 | M23: ='SEPTEMBER'!F15 | N23: ='OCTOBER'!F15 | O23: ='NOVEMBER'!F15 | P23: ='DECEMBER'!F15 | Q23: =SUM(E23:P23)
B24: MARCH | D24: Transportation | E24: ='JANUARY'!F16 | F24: ='FEBRUARY'!F16 | G24: ='MARCH'!F16 | H24: ='APRIL'!F16 | I24: ='MAY'!F16 | J24: ='JUNE'!F16 | K24: ='JULY'!F16 | L24: ='AUGUST'!F16 | M24: ='SEPTEMBER'!F16 | N24: ='OCTOBER'!F16 | O24: ='NOVEMBER'!F16 | P24: ='DECEMBER'!F16 | Q24: =SUM(E24:P24)
B25: APRIL | D25: Food & Dining | E25: ='JANUARY'!F17 | F25: ='FEBRUARY'!F17 | G25: ='MARCH'!F17 | H25: ='APRIL'!F17 | I25: ='MAY'!F17 | J25: ='JUNE'!F17 | K25: ='JULY'!F17 | L25: ='AUGUST'!F17 | M25: ='SEPTEMBER'!F17 | N25: ='OCTOBER'!F17 | O25: ='NOVEMBER'!F17 | P25: ='DECEMBER'!F17 | Q25: =SUM(E25:P25)
B26: MAY | D26: Utilities | E26: ='JANUARY'!F18 | F26: ='FEBRUARY'!F18 | G26: ='MARCH'!F18 | H26: ='APRIL'!F18 | I26: ='MAY'!F18 | J26: ='JUNE'!F18 | K26: ='JULY'!F18 | L26: ='AUGUST'!F18 | M26: ='SEPTEMBER'!F18 | N26: ='OCTOBER'!F18 | O26: ='NOVEMBER'!F18 | P26: ='DECEMBER'!F18 | Q26: =SUM(E26:P26)
B27: JUNE | D27: Healthcare | E27: ='JANUARY'!F19 | F27: ='FEBRUARY'!F19 | G27: ='MARCH'!F19 | H27: ='APRIL'!F19 | I27: ='MAY'!F19 | J27: ='JUNE'!F19 | K27: ='JULY'!F19 | L27: ='AUGUST'!F19 | M27: ='SEPTEMBER'!F19 | N27: ='OCTOBER'!F19 | O27: ='NOVEMBER'!F19 | P27: ='DECEMBER'!F19 | Q27: =SUM(E27:P27)
B28: JULY | D28: Insurance | E28: ='JANUARY'!F20 | F28: ='FEBRUARY'!F20 | G28: ='MARCH'!F20 | H28: ='APRIL'!F20 | I28: ='MAY'!F20 | J28: ='JUNE'!F20 | K28: ='JULY'!F20 | L28: ='AUGUST'!F20 | M28: ='SEPTEMBER'!F20 | N28: ='OCTOBER'!F20 | O28: ='NOVEMBER'!F20 | P28: ='DECEMBER'!F20 | Q28: =SUM(E28:P28)
B29: AUGUST | D29: Entertainment | E29: ='JANUARY'!F21 | F29: ='FEBRUARY'!F21 | G29: ='MARCH'!F21 | H29: ='APRIL'!F21 | I29: ='MAY'!F21 | J29: ='JUNE'!F21 | K29: ='JULY'!F21 | L29: ='AUGUST'!F21 | M29: ='SEPTEMBER'!F21 | N29: ='OCTOBER'!F21 | O29: ='NOVEMBER'!F21 | P29: ='DECEMBER'!F21 | Q29: =SUM(E29:P29)
B30: SEPTEMBER | D30: Shopping | E30: ='JANUARY'!F22 | F30: ='FEBRUARY'!F22 | G30: ='MARCH'!F22 | H30: ='APRIL'!F22 | I30: ='MAY'!F22 | J30: ='JUNE'!F22 | K30: ='JULY'!F22 | L30: ='AUGUST'!F22 | M30: ='SEPTEMBER'!F22 | N30: ='OCTOBER'!F22 | O30: ='NOVEMBER'!F22 | P30: ='DECEMBER'!F22 | Q30: =SUM(E30:P30)
B31: OCTOBER | D31: Personal Care | E31: ='JANUARY'!F23 | F31: ='FEBRUARY'!F23 | G31: ='MARCH'!F23 | H31: ='APRIL'!F23 | I31: ='MAY'!F23 | J31: ='JUNE'!F23 | K31: ='JULY'!F23 | L31: ='AUGUST'!F23 | M31: ='SEPTEMBER'!F23 | N31: ='OCTOBER'!F23 | O31: ='NOVEMBER'!F23 | P31: ='DECEMBER'!F23 | Q31: =SUM(E31:P31)
B32: NOVEMBER | D32: Education | E32: ='JANUARY'!F24 | F32: ='FEBRUARY'!F24 | G32: ='MARCH'!F24 | H32: ='APRIL'!F24 | I32: ='MAY'!F24 | J32: ='JUNE'!F24 | K32: ='JULY'!F24 | L32: ='AUGUST'!F24 | M32: ='SEPTEMBER'!F24 | N32: ='OCTOBER'!F24 | O32: ='NOVEMBER'!F24 | P32: ='DECEMBER'!F24 | Q32: =SUM(E32:P32)
B33: DECEMBER | D33: Savings | E33: ='JANUARY'!F25 | F33: ='FEBRUARY'!F25 | G33: ='MARCH'!F25 | H33: ='APRIL'!F25 | I33: ='MAY'!F25 | J33: ='JUNE'!F25 | K33: ='JULY'!F25 | L33: ='AUGUST'!F25 | M33: ='SEPTEMBER'!F25 | N33: ='OCTOBER'!F25 | O33: ='NOVEMBER'!F25 | P33: ='DECEMBER'!F25 | Q33: =SUM(E33:P33)
D34: Investments | E34: ='JANUARY'!F26 | F34: ='FEBRUARY'!F26 | G34: ='MARCH'!F26 | H34: ='APRIL'!F26 | I34: ='MAY'!F26 | J34: ='JUNE'!F26 | K34: ='JULY'!F26 | L34: ='AUGUST'!F26 | M34: ='SEPTEMBER'!F26 | N34: ='OCTOBER'!F26 | O34: ='NOVEMBER'!F26 | P34: ='DECEMBER'!F26 | Q34: =SUM(E34:P34)
B35: TOOLS | D35: Debt Payments | E35: ='JANUARY'!F27 | F35: ='FEBRUARY'!F27 | G35: ='MARCH'!F27 | H35: ='APRIL'!F27 | I35: ='MAY'!F27 | J35: ='JUNE'!F27 | K35: ='JULY'!F27 | L35: ='AUGUST'!F27 | M35: ='SEPTEMBER'!F27 | N35: ='OCTOBER'!F27 | O35: ='NOVEMBER'!F27 | P35: ='DECEMBER'!F27 | Q35: =SUM(E35:P35)
B36: 50-30-20 | D36: Gifts & Donations | E36: ='JANUARY'!F28 | F36: ='FEBRUARY'!F28 | G36: ='MARCH'!F28 | H36: ='APRIL'!F28 | I36: ='MAY'!F28 | J36: ='JUNE'!F28 | K36: ='JULY'!F28 | L36: ='AUGUST'!F28 | M36: ='SEPTEMBER'!F28 | N36: ='OCTOBER'!F28 | O36: ='NOVEMBER'!F28 | P36: ='DECEMBER'!F28 | Q36: =SUM(E36:P36)
B37: EXPENSE DIST | D37: Other | E37: ='JANUARY'!F29 | F37: ='FEBRUARY'!F29 | G37: ='MARCH'!F29 | H37: ='APRIL'!F29 | I37: ='MAY'!F29 | J37: ='JUNE'!F29 | K37: ='JULY'!F29 | L37: ='AUGUST'!F29 | M37: ='SEPTEMBER'!F29 | N37: ='OCTOBER'!F29 | O37: ='NOVEMBER'!F29 | P37: ='DECEMBER'!F29 | Q37: =SUM(E37:P37)
B38: SINKING FUNDS
B39: DEBT CALC
B40: NET WORTH
B41: INVEST FORECAST
B42: NO-SPEND

Sheet CALENDAR
B2: PLANWISE HAUS | D2: PLANWISE HAUS · AUTOMATED BILL CALENDAR
D3: EXCEL TEMPLATES FOR LIFE & HOME
B5: OVERVIEW | D5: ANNUAL BILL PAYMENT CALENDAR
B6: INSTRUCTIONS | D6: Bill Name | E6: Amt | F6: JAN | G6: FEB | H6: MAR | I6: APR | J6: MAY | K6: JUN | L6: JUL | M6: AUG | N6: SEP | O6: OCT | P6: NOV | Q6: DEC
B7: SETUP | D7: Rent / Mortgage | E7: 1500 | F7: Due 1 | G7: Due 1 | H7: Due 1 | I7: Due 1 | J7: Due 1 | K7: Due 1 | L7: Due 1 | M7: Due 1 | N7: Due 1 | O7: Due 1 | P7: Due 1 | Q7: Due 1
B8: DASHBOARD | D8: Car Payment | E8: 385 | F8: Due 15 | G8: Due 15 | H8: Due 15 | I8: Due 15 | J8: Due 15 | K8: Due 15 | L8: Due 15 | M8: Due 15 | N8: Due 15 | O8: Due 15 | P8: Due 15 | Q8: Due 15
D9: Electric | E9: 120 | F9: Due 10 | G9: Due 10 | H9: Due 10 | I9: Due 10 | J9: Due 10 | K9: Due 10 | L9: Due 10 | M9: Due 10 | N9: Due 10 | O9: Due 10 | P9: Due 10 | Q9: Due 10
B10: ACCOUNTS | D10: Internet | E10: 65 | F10: Due 20 | G10: Due 20 | H10: Due 20 | I10: Due 20 | J10: Due 20 | K10: Due 20 | L10: Due 20 | M10: Due 20 | N10: Due 20 | O10: Due 20 | P10: Due 20 | Q10: Due 20
B11: BANK ACCOUNTS | D11: Phone | E11: 80 | F11: Due 25 | G11: Due 25 | H11: Due 25 | I11: Due 25 | J11: Due 25 | K11: Due 25 | L11: Due 25 | M11: Due 25 | N11: Due 25 | O11: Due 25 | P11: Due 25 | Q11: Due 25
B12: RECURRING | D12: Health Insurance | E12: 220 | F12: Due 1 | G12: Due 1 | H12: Due 1 | I12: Due 1 | J12: Due 1 | K12: Due 1 | L12: Due 1 | M12: Due 1 | N12: Due 1 | O12: Due 1 | P12: Due 1 | Q12: Due 1
B13: PAYMENTS | D13: Car Insurance | E13: 145 | F13: Due 1 | G13: Due 1 | H13: Due 1 | I13: Due 1 | J13: Due 1 | K13: Due 1 | L13: Due 1 | M13: Due 1 | N13: Due 1 | O13: Due 1 | P13: Due 1 | Q13: Due 1
B14: VARIABLE | D14: Gym | E14: 45 | F14: Due 1 | G14: Due 1 | H14: Due 1 | I14: Due 1 | J14: Due 1 | K14: Due 1 | L14: Due 1 | M14: Due 1 | N14: Due 1 | O14: Due 1 | P14: Due 1 | Q14: Due 1
D15: Netflix | E15: 15.99 | F15: Due 7 | G15: Due 7 | H15: Due 7 | I15: Due 7 | J15: Due 7 | K15: Due 7 | L15: Due 7 | M15: Due 7 | N15: Due 7 | O15: Due 7 | P15: Due 7 | Q15: Due 7
B16: ANALYTICS | D16: Spotify | E16: 9.99 | F16: Due 14 | G16: Due 14 | H16: Due 14 | I16: Due 14 | J16: Due 14 | K16: Due 14 | L16: Due 14 | M16: Due 14 | N16: Due 14 | O16: Due 14 | P16: Due 14 | Q16: Due 14
B17: ANNUAL TOTALS
B18: PAYCHECK | D18: MONTHLY TOTAL | E18: =SUM(E7:E17)
B19: CALENDAR
B21: MONTHLY
B22: JANUARY
B23: FEBRUARY
B24: MARCH
B25: APRIL
B26: MAY
B27: JUNE
B28: JULY
B29: AUGUST
B30: SEPTEMBER
B31: OCTOBER
... B42: NO-SPEND

Sheet PAYCHECK
B2: PLANWISE HAUS | D2: PLANWISE HAUS · PAYCHECK DASHBOARD
D3: EXCEL TEMPLATES FOR LIFE & HOME
B5: OVERVIEW | D5: PAYCHECK LOG
B6: INSTRUCTIONS | D6: Pay Date | E6: Pay Period | F6: Gross Pay | G6: Federal Tax | H6: State Tax | I6: Other Deductions | J6: Net Pay
B7: SETUP | D7: 01/15/2025 | E7: Jan 1–15 | F7: 2500 | G7: 375 | H7: 125 | I7: 185 | J7: =E7-F7-G7-H7
B8: DASHBOARD | D8: 01/31/2025 | E8: Jan 16–31 | F8: 2500 | G8: 375 | H8: 125 | I8: 185 | J8: =E8-F8-G8-H8
D9: 02/14/2025 | E9: Feb 1–14 | F9: 2500 | G9: 375 | H9: 125 | I9: 185 | J9: =E9-F9-G9-H9
B10: ACCOUNTS | D10: 02/28/2025 | E10: Feb 15–28 | F10: 2500 | G10: 375 | H10: 125 | I10: 185 | J10: =E10-F10-G10-H10
B11: BANK ACCOUNTS | D11: 03/15/2025 | E11: Mar 1–15 | F11: 2500 | G11: 375 | H11: 125 | I11: 185 | J11: =E11-F11-G11-H11
B12: RECURRING
B13: PAYMENTS | D13: YTD TOTALS | E13: =SUM(E7:E12) | F13: =SUM(F7:F12) | G13: =SUM(G7:G12) | H13: =SUM(H7:H12) | I13: =SUM(I7:I12) | J13: =SUM(J7:J12)
B14: VARIABLE
D15: YTD SUMMARY
B16: ANALYTICS
B17: ANNUAL TOTALS | D17: =E13 | I17: =J13 | N17: =IF(E13>0,(F13+G13)/E13,0)
B18: PAYCHECK | D18: YTD GROSS PAY | I18: YTD NET PAY | N18: EFFECTIVE TAX RATE
B19: CALENDAR
B21: MONTHLY
B22: JANUARY
B23: FEBRUARY
B24: MARCH
B25: APRIL
B26: MAY
B27: JUNE
B28: JULY
B29: AUGUST
B30: SEPTEMBER
B31: OCTOBER
... B42: NO-SPEND

Sheet JANUARY
B2: PLANWISE HAUS | D2: PLANWISE HAUS · JANUARY
D3: EXCEL TEMPLATES FOR LIFE & HOME
B5: OVERVIEW | D5: INCOME — JANUARY 2025
B6: INSTRUCTIONS | D6: Source | E6: Budgeted | F6: Actual | G6: Difference | H6: Notes
B7: SETUP | D7: Primary Salary | E7: 5000 | F7: 5000 | G7: =F7-E7
B8: DASHBOARD | D8: Side Income | E8: 500 | F8: 0 | G8: =F8-E8
D9: Other | E9: 0 | F9: 0 | G9: =F9-E9
B10: ACCOUNTS
B11: BANK ACCOUNTS | D11: TOTAL INCOME | E11: =SUM(E7:E10) | F11: =SUM(F7:F10)
B12: RECURRING
B13: PAYMENTS | D13: EXPENSES — JANUARY 2025
B14: VARIABLE | D14: Category | E14: Budget | F14: Actual Spent | G14: Remaining | H14: % Used | I14: Notes
D15: Housing | E15: 1500 | F15: 0 | G15: =E15-F15 | H15: =IF(E15>0,F15/E15,0)
B16: ANALYTICS | D16: Transportation | E16: 400 | F16: 0 | G16: =E16-F16 | H16: =IF(E16>0,F16/E16,0)
B17: ANNUAL TOTALS | D17: Food & Dining | E17: 600 | F17: 0 | G17: =E17-F17 | H17: =IF(E17>0,F17/E17,0)
B18: PAYCHECK | D18: Utilities | E18: 200 | F18: 0 | G18: =E18-F18 | H18: =IF(E18>0,F18/E18,0)
B19: CALENDAR | D19: Healthcare | E19: 150 | F19: 0 | G19: =E19-F19 | H19: =IF(E19>0,F19/E19,0)
D20: Insurance | E20: 250 | F20: 0 | G20: =E20-F20 | H20: =IF(E20>0,F20/E20,0)
B21: MONTHLY | D21: Entertainment | E21: 150 | F21: 0 | G21: =E21-F21 | H21: =IF(E21>0,F21/E21,0)
B22: JANUARY | D22: Shopping | E22: 200 | F22: 0 | G22: =E22-F22 | H22: =IF(E22>0,F22/E22,0)
B23: FEBRUARY | D23: Personal Care | E23: 100 | F23: 0 | G23: =E23-F23 | H23: =IF(E23>0,F23/E23,0)
B24: MARCH | D24: Education | E24: 50 | F24: 0 | G24: =E24-F24 | H24: =IF(E24>0,F24/E24,0)
B25: APRIL | D25: Savings | E25: 500 | F25: 0 | G25: =E25-F25 | H25: =IF(E25>0,F25/E25,0)
B26: MAY | D26: Investments | E26: 300 | F26: 0 | G26: =E26-F26 | H26: =IF(E26>0,F26/E26,0)
B27: JUNE | D27: Debt Payments | E27: 200 | F27: 0 | G27: =E27-F27 | H27: =IF(E27>0,F27/E27,0)
B28: JULY | D28: Gifts & Donations | E28: 100 | F28: 0 | G28: =E28-F28 | H28: =IF(E28>0,F28/E28,0)
B29: AUGUST | D29: Other | E29: 100 | F29: 0 | G29: =E29-F29 | H29: =IF(E29>0,F29/E29,0)
B30: SEPTEMBER | D30: TOTAL EXPENSES | E30: =SUM(E15:E29) | F30: =SUM(F15:F29) | G30: =SUM(G15:G29)
B31: OCTOBER
B32: NOVEMBER | D32: MONTHLY SUMMARY
B33: DECEMBER | D33: Net Savings (Actual Income − Actual Expenses) | G33: =F11-F30
B35: TOOLS
B36: 50-30-20
B37: EXPENSE DIST
B38: SINKING FUNDS
B39: DEBT CALC
B40: NET WORTH
B41: INVEST FORECAST
B42: NO-SPEND

Sheet FEBRUARY
B2: PLANWISE HAUS | D2: PLANWISE HAUS · FEBRUARY
D3: EXCEL TEMPLATES FOR LIFE & HOME
B5: OVERVIEW | D5: INCOME — FEBRUARY 2025
B6: INSTRUCTIONS | D6: Source | E6: Budgeted | F6: Actual | G6: Difference | H6: Notes
B7: SETUP | D7: Primary Salary | E7: 5000 | F7: 5000 | G7: =F7-E7
B8: DASHBOARD | D8: Side Income | E8: 500 | F8: 0 | G8: =F8-E8
D9: Other | E9: 0 | F9: 0 | G9: =F9-E9
B10: ACCOUNTS
B11: BANK ACCOUNTS | D11: TOTAL INCOME | E11: =SUM(E7:E10) | F11: =SUM(F7:F10)
B12: RECURRING
B13: PAYMENTS | D13: EXPENSES — FEBRUARY 2025
B14: VARIABLE | D14: Category | E14: Budget | F14: Actual Spent | G14: Remaining | H14: % Used | I14: Notes
D15: Housing | E15: 1500 | F15: 0 | G15: =E15-F15 | H15: =IF(E15>0,F15/E15,0)
B16: ANALYTICS | D16: Transportation | E16: 400 | F16: 0 | G16: =E16-F16 | H16: =IF(E16>0,F16/E16,0)
B17: ANNUAL TOTALS | D17: Food & Dining | E17: 600 | F17: 0 | G17: =E17-F17 | H17: =IF(E17>0,F17/E17,0)
B18: PAYCHECK | D18: Utilities | E18: 200 | F18: 0 | G18: =E18-F18 | H18: =IF(E18>0,F18/E18,0)
B19: CALENDAR | D19: Healthcare | E19: 150 | F19: 0 | G19: =E19-F19 | H19: =IF(E19>0,F19/E19,0)
D20: Insurance | E20: 250 | F20: 0 | G20: =E20-F20 | H20: =IF(E20>0,F20/E20,0)
B21: MONTHLY | D21: Entertainment | E21: 150 | F21: 0 | G21: =E21-F21 | H21: =IF(E21>0,F21/E21,0)
B22: JANUARY | D22: Shopping | E22: 200 | F22: 0 | G22: =E22-F22 | H22: =IF(E22>0,F22/E22,0)
B23: FEBRUARY | D23: Personal Care | E23: 100 | F23: 0 | G23: =E23-F23 | H23: =IF(E23>0,F23/E23,0)
B24: MARCH | D24: Education | E24: 50 | F24: 0 | G24: =E24-F24 | H24: =IF(E24>0,F24/E24,0)
B25: APRIL | D25: Savings | E25: 500 | F25: 0 | G25: =E25-F25 | H25: =IF(E25>0,F25/E25,0)
B26: MAY | D26: Investments | E26: 300 | F26: 0 | G26: =E26-F26 | H26: =IF(E26>0,F26/E26,0)
B27: JUNE | D27: Debt Payments | E27: 200 | F27: 0 | G27: =E27-F27 | H27: =IF(E27>0,F27/E27,0)
B28: JULY | D28: Gifts & Donations | E28: 100 | F28: 0 | G28: =E28-F28 | H28: =IF(E28>0,F28/E28,0)
B29: AUGUST | D29: Other | E29: 100 | F29: 0 | G29: =E29-F29 | H29: =IF(E29>0,F29/E29,0)
B30: SEPTEMBER | D30: TOTAL EXPENSES | E30: =SUM(E15:E29) | F30: =SUM(F15:F29) | G30: =SUM(G15:G29)
B31: OCTOBER
B32: NOVEMBER | D32: MONTHLY SUMMARY
B33: DECEMBER | D33: Net Savings (Actual Income − Actual Expenses) | G33: =F11-F30
B35: TOOLS
B36: 50-30-20
B37: EXPENSE DIST
B38: SINKING FUNDS
B39: DEBT CALC
B40: NET WORTH
B41: INVEST FORECAST
B42: NO-SPEND

Sheet MARCH
B2: PLANWISE HAUS | D2: PLANWISE HAUS · MARCH
D3: EXCEL TEMPLATES FOR LIFE & HOME
B5: OVERVIEW | D5: INCOME — MARCH 2025
B6: INSTRUCTIONS | D6: Source | E6: Budgeted | F6: Actual | G6: Difference | H6: Notes
B7: SETUP | D7: Primary Salary | E7: 5000 | F7: 5000 | G7: =F7-E7
B8: DASHBOARD | D8: Side Income | E8: 500 | F8: 0 | G8: =F8-E8
D9: Other | E9: 0 | F9: 0 | G9: =F9-E9
B10: ACCOUNTS
B11: BANK ACCOUNTS | D11: TOTAL INCOME | E11: =SUM(E7:E10) | F11: =SUM(F7:F10)
B12: RECURRING
B13: PAYMENTS | D13: EXPENSES — MARCH 2025
B14: VARIABLE | D14: Category | E14: Budget | F14: Actual Spent | G14: Remaining | H14: % Used | I14: Notes
D15: Housing | E15: 1500 | F15: 0 | G15: =E15-F15 | H15: =IF(E15>0,F15/E15,0)
B16: ANALYTICS | D16: Transportation | E16: 400 | F16: 0 | G16: =E16-F16 | H16: =IF(E16>0,F16/E16,0)
B17: ANNUAL TOTALS | D17: Food & Dining | E17: 600 | F17: 0 | G17: =E17-F17 | H17: =IF(E17>0,F17/E17,0)
B18: PAYCHECK | D18: Utilities | E18: 200 | F18: 0 | G18: =E18-F18 | H18: =IF(E18>0,F18/E18,0)
B19: CALENDAR | D19: Healthcare | E19: 150 | F19: 0 | G19: =E19-F19 | H19: =IF(E19>0,F19/E19,0)
D20: Insurance | E20: 250 | F20: 0 | G20: =E20-F20 | H20: =IF(E20>0,F20/E20,0)
B21: MONTHLY | D21: Entertainment | E21: 150 | F21: 0 | G21: =E21-F21 | H21: =IF(E21>0,F21/E21,0)
B22: JANUARY | D22: Shopping | E22: 200 | F22: 0 | G22: =E22-F22 | H22: =IF(E22>0,F22/E22,0)
B23: FEBRUARY | D23: Personal Care | E23: 100 | F23: 0 | G23: =E23-F23 | H23: =IF(E23>0,F23/E23,0)
B24: MARCH | D24: Education | E24: 50 | F24: 0 | G24: =E24-F24 | H24: =IF(E24>0,F24/E24,0)
B25: APRIL | D25: Savings | E25: 500 | F25: 0 | G25: =E25-F25 | H25: =IF(E25>0,F25/E25,0)
B26: MAY | D26: Investments | E26: 300 | F26: 0 | G26: =E26-F26 | H26: =IF(E26>0,F26/E26,0)
B27: JUNE | D27: Debt Payments | E27: 200 | F27: 0 | G27: =E27-F27 | H27: =IF(E27>0,F27/E27,0)
B28: JULY | D28: Gifts & Donations | E28: 100 | F28: 0 | G28: =E28-F28 | H28: =IF(E28>0,F28/E28,0)
B29: AUGUST | D29: Other | E29: 100 | F29: 0 | G29: =E29-F29 | H29: =IF(E29>0,F29/E29,0)
B30: SEPTEMBER | D30: TOTAL EXPENSES | E30: =SUM(E15:E29) | F30: =SUM(F15:F29) | G30: =SUM(G15:G29)
B31: OCTOBER
B32: NOVEMBER | D32: MONTHLY SUMMARY
B33: DECEMBER | D33: Net Savings (Actual Income − Actual Expenses) | G33: =F11-F30
B35: TOOLS
B36: 50-30-20
B37: EXPENSE DIST
B38: SINKING FUNDS
B39: DEBT CALC
B40: NET WORTH
B41: INVEST FORECAST
B42: NO-SPEND

Sheet APRIL
B2: PLANWISE HAUS | D2: PLANWISE HAUS · APRIL
D3: EXCEL TEMPLATES FOR LIFE & HOME
B5: OVERVIEW | D5: INCOME — APRIL 2025
B6: INSTRUCTIONS | D6: Source | E6: Budgeted | F6: Actual | G6: Difference | H6: Notes
B7: SETUP | D7: Primary Salary | E7: 5000 | F7: 5000 | G7: =F7-E7
B8: DASHBOARD | D8: Side Income | E8: 500 | F8: 0 | G8: =F8-E8
D9: Other | E9: 0 | F9: 0 | G9: =F9-E9
B10: ACCOUNTS
B11: BANK ACCOUNTS | D11: TOTAL INCOME | E11: =SUM(E7:E10) | F11: =SUM(F7:F10)
B12: RECURRING
B13: PAYMENTS | D13: EXPENSES — APRIL 2025
B14: VARIABLE | D14: Category | E14: Budget | F14: Actual Spent | G14: Remaining | H14: % Used | I14: Notes
D15: Housing | E15: 1500 | F15: 0 | G15: =E15-F15 | H15: =IF(E15>0,F15/E15,0)
B16: ANALYTICS | D16: Transportation | E16: 400 | F16: 0 | G16: =E16-F16 | H16: =IF(E16>0,F16/E16,0)
B17: ANNUAL TOTALS | D17: Food & Dining | E17: 600 | F17: 0 | G17: =E17-F17 | H17: =IF(E17>0,F17/E17,0)
B18: PAYCHECK | D18: Utilities | E18: 200 | F18: 0 | G18: =E18-F18 | H18: =IF(E18>0,F18/E18,0)
B19: CALENDAR | D19: Healthcare | E19: 150 | F19: 0 | G19: =E19-F19 | H19: =IF(E19>0,F19/E19,0)
D20: Insurance | E20: 250 | F20: 0 | G20: =E20-F20 | H20: =IF(E20>0,F20/E20,0)
B21: MONTHLY | D21: Entertainment | E21: 150 | F21: 0 | G21: =E21-F21 | H21: =IF(E21>0,F21/E21,0)
B22: JANUARY | D22: Shopping | E22: 200 | F22: 0 | G22: =E22-F22 | H22: =IF(E22>0,F22/E22,0)
B23: FEBRUARY | D23: Personal Care | E23: 100 | F23: 0 | G23: =E23-F23 | H23: =IF(E23>0,F23/E23,0)
B24: MARCH | D24: Education | E24: 50 | F24: 0 | G24: =E24-F24 | H24: =IF(E24>0,F24/E24,0)
B25: APRIL | D25: Savings | E25: 500 | F25: 0 | G25: =E25-F25 | H25: =IF(E25>0,F25/E25,0)
B26: MAY | D26: Investments | E26: 300 | F26: 0 | G26: =E26-F26 | H26: =IF(E26>0,F26/E26,0)
B27: JUNE | D27: Debt Payments | E27: 200 | F27: 0 | G27: =E27-F27 | H27: =IF(E27>0,F27/E27,0)
B28: JULY | D28: Gifts & Donations | E28: 100 | F28: 0 | G28: =E28-F28 | H28: =IF(E28>0,F28/E28,0)
B29: AUGUST | D29: Other | E29: 100 | F29: 0 | G29: =E29-F29 | H29: =IF(E29>0,F29/E29,0)
B30: SEPTEMBER | D30: TOTAL EXPENSES | E30: =SUM(E15:E29) | F30: =SUM(F15:F29) | G30: =SUM(G15:G29)
B31: OCTOBER
B32: NOVEMBER | D32: MONTHLY SUMMARY
B33: DECEMBER | D33: Net Savings (Actual Income − Actual Expenses) | G33: =F11-F30
B35: TOOLS
B36: 50-30-20
B37: EXPENSE DIST
B38: SINKING FUNDS
B39: DEBT CALC
B40: NET WORTH
B41: INVEST FORECAST
B42: NO-SPEND

Sheet MAY
B2: PLANWISE HAUS | D2: PLANWISE HAUS · MAY
D3: EXCEL TEMPLATES FOR LIFE & HOME
B5: OVERVIEW | D5: INCOME — MAY 2025
B6: INSTRUCTIONS | D6: Source | E6: Budgeted | F6: Actual | G6: Difference | H6: Notes
B7: SETUP | D7: Primary Salary | E7: 5000 | F7: 5000 | G7: =F7-E7
B8: DASHBOARD | D8: Side Income | E8: 500 | F8: 0 | G8: =F8-E8
D9: Other | E9: 0 | F9: 0 | G9: =F9-E9
B10: ACCOUNTS
B11: BANK ACCOUNTS | D11: TOTAL INCOME | E11: =SUM(E7:E10) | F11: =SUM(F7:F10)
B12: RECURRING
B13: PAYMENTS | D13: EXPENSES — MAY 2025
B14: VARIABLE | D14: Category | E14: Budget | F14: Actual Spent | G14: Remaining | H14: % Used | I14: Notes
D15: Housing | E15: 1500 | F15: 0 | G15: =E15-F15 | H15: =IF(E15>0,F15/E15,0)
B16: ANALYTICS | D16: Transportation | E16: 400 | F16: 0 | G16: =E16-F16 | H16: =IF(E16>0,F16/E16,0)
B17: ANNUAL TOTALS | D17: Food & Dining | E17: 600 | F17: 0 | G17: =E17-F17 | H17: =IF(E17>0,F17/E17,0)
B18: PAYCHECK | D18: Utilities | E18: 200 | F18: 0 | G18: =E18-F18 | H18: =IF(E18>0,F18/E18,0)
B19: CALENDAR | D19: Healthcare | E19: 150 | F19: 0 | G19: =E19-F19 | H19: =IF(E19>0,F19/E19,0)
D20: Insurance | E20: 250 | F20: 0 | G20: =E20-F20 | H20: =IF(E20>0,F20/E20,0)
B21: MONTHLY | D21: Entertainment | E21: 150 | F21: 0 | G21: =E21-F21 | H21: =IF(E21>0,F21/E21,0)
B22: JANUARY | D22: Shopping | E22: 200 | F22: 0 | G22: =E22-F22 | H22: =IF(E22>0,F22/E22,0)
B23: FEBRUARY | D23: Personal Care | E23: 100 | F23: 0 | G23: =E23-F23 | H23: =IF(E23>0,F23/E23,0)
B24: MARCH | D24: Education | E24: 50 | F24: 0 | G24: =E24-F24 | H24: =IF(E24>0,F24/E24,0)
B25: APRIL | D25: Savings | E25: 500 | F25: 0 | G25: =E25-F25 | H25: =IF(E25>0,F25/E25,0)
B26: MAY | D26: Investments | E26: 300 | F26: 0 | G26: =E26-F26 | H26: =IF(E26>0,F26/E26,0)
B27: JUNE | D27: Debt Payments | E27: 200 | F27: 0 | G27: =E27-F27 | H27: =IF(E27>0,F27/E27,0)
B28: JULY | D28: Gifts & Donations | E28: 100 | F28: 0 | G28: =E28-F28 | H28: =IF(E28>0,F28/E28,0)
B29: AUGUST | D29: Other | E29: 100 | F29: 0 | G29: =E29-F29 | H29: =IF(E29>0,F29/E29,0)
B30: SEPTEMBER | D30: TOTAL EXPENSES | E30: =SUM(E15:E29) | F30: =SUM(F15:F29) | G30: =SUM(G15:G29)
B31: OCTOBER
B32: NOVEMBER | D32: MONTHLY SUMMARY
B33: DECEMBER | D33: Net Savings (Actual Income − Actual Expenses) | G33: =F11-F30
B35: TOOLS
B36: 50-30-20
B37: EXPENSE DIST
B38: SINKING FUNDS
B39: DEBT CALC
B40: NET WORTH
B41: INVEST FORECAST
B42: NO-SPEND

Sheet JUNE
B2: PLANWISE HAUS | D2: PLANWISE HAUS · JUNE
D3: EXCEL TEMPLATES FOR LIFE & HOME
B5: OVERVIEW | D5: INCOME — JUNE 2025
B6: INSTRUCTIONS | D6: Source | E6: Budgeted | F6: Actual | G6: Difference | H6: Notes
B7: SETUP | D7: Primary Salary | E7: 5000 | F7: 5000 | G7: =F7-E7
B8: DASHBOARD | D8: Side Income | E8: 500 | F8: 0 | G8: =F8-E8
D9: Other | E9: 0 | F9: 0 | G9: =F9-E9
B10: ACCOUNTS
B11: BANK ACCOUNTS | D11: TOTAL INCOME | E11: =SUM(E7:E10) | F11: =SUM(F7:F10)
B12: RECURRING
B13: PAYMENTS | D13: EXPENSES — JUNE 2025
B14: VARIABLE | D14: Category | E14: Budget | F14: Actual Spent | G14: Remaining | H14: % Used | I14: Notes
D15: Housing | E15: 1500 | F15: 0 | G15: =E15-F15 | H15: =IF(E15>0,F15/E15,0)
B16: ANALYTICS | D16: Transportation | E16: 400 | F16: 0 | G16: =E16-F16 | H16: =IF(E16>0,F16/E16,0)
B17: ANNUAL TOTALS | D17: Food & Dining | E17: 600 | F17: 0 | G17: =E17-F17 | H17: =IF(E17>0,F17/E17,0)
B18: PAYCHECK | D18: Utilities | E18: 200 | F18: 0 | G18: =E18-F18 | H18: =IF(E18>0,F18/E18,0)
B19: CALENDAR | D19: Healthcare | E19: 150 | F19: 0 | G19: =E19-F19 | H19: =IF(E19>0,F19/E19,0)
D20: Insurance | E20: 250 | F20: 0 | G20: =E20-F20 | H20: =IF(E20>0,F20/E20,0)
B21: MONTHLY | D21: Entertainment | E21: 150 | F21: 0 | G21: =E21-F21 | H21: =IF(E21>0,F21/E21,0)
B22: JANUARY | D22: Shopping | E22: 200 | F22: 0 | G22: =E22-F22 | H22: =IF(E22>0,F22/E22,0)
B23: FEBRUARY | D23: Personal Care | E23: 100 | F23: 0 | G23: =E23-F23 | H23: =IF(E23>0,F23/E23,0)
B24: MARCH | D24: Education | E24: 50 | F24: 0 | G24: =E24-F24 | H24: =IF(E24>0,F24/E24,0)
B25: APRIL | D25: Savings | E25: 500 | F25: 0 | G25: =E25-F25 | H25: =IF(E25>0,F25/E25,0)
B26: MAY | D26: Investments | E26: 300 | F26: 0 | G26: =E26-F26 | H26: =IF(E26>0,F26/E26,0)
B27: JUNE | D27: Debt Payments | E27: 200 | F27: 0 | G27: =E27-F27 | H27: =IF(E27>0,F27/E27,0)
B28: JULY | D28: Gifts & Donations | E28: 100 | F28: 0 | G28: =E28-F28 | H28: =IF(E28>0,F28/E28,0)
B29: AUGUST | D29: Other | E29: 100 | F29: 0 | G29: =E29-F29 | H29: =IF(E29>0,F29/E29,0)
B30: SEPTEMBER | D30: TOTAL EXPENSES | E30: =SUM(E15:E29) | F30: =SUM(F15:F29) | G30: =SUM(G15:G29)
B31: OCTOBER
B32: NOVEMBER | D32: MONTHLY SUMMARY
B33: DECEMBER | D33: Net Savings (Actual Income − Actual Expenses) | G33: =F11-F30
B35: TOOLS
B36: 50-30-20
B37: EXPENSE DIST
B38: SINKING FUNDS
B39: DEBT CALC
B40: NET WORTH
B41: INVEST FORECAST
B42: NO-SPEND

Sheet JULY
B2: PLANWISE HAUS | D2: PLANWISE HAUS · JULY
D3: EXCEL TEMPLATES FOR LIFE & HOME
B5: OVERVIEW | D5: INCOME — JULY 2025
B6: INSTRUCTIONS | D6: Source | E6: Budgeted | F6: Actual | G6: Difference | H6: Notes
B7: SETUP | D7: Primary Salary | E7: 5000 | F7: 5000 | G7: =F7-E7
B8: DASHBOARD | D8: Side Income | E8: 500 | F8: 0 | G8: =F8-E8
D9: Other | E9: 0 | F9: 0 | G9: =F9-E9
B10: ACCOUNTS
B11: BANK ACCOUNTS | D11: TOTAL INCOME | E11: =SUM(E7:E10) | F11: =SUM(F7:F10)
B12: RECURRING
B13: PAYMENTS | D13: EXPENSES — JULY 2025
B14: VARIABLE | D14: Category | E14: Budget | F14: Actual Spent | G14: Remaining | H14: % Used | I14: Notes
D15: Housing | E15: 1500 | F15: 0 | G15: =E15-F15 | H15: =IF(E15>0,F15/E15,0)
B16: ANALYTICS | D16: Transportation | E16: 400 | F16: 0 | G16: =E16-F16 | H16: =IF(E16>0,F16/E16,0)
B17: ANNUAL TOTALS | D17: Food & Dining | E17: 600 | F17: 0 | G17: =E17-F17 | H17: =IF(E17>0,F17/E17,0)
B18: PAYCHECK | D18: Utilities | E18: 200 | F18: 0 | G18: =E18-F18 | H18: =IF(E18>0,F18/E18,0)
B19: CALENDAR | D19: Healthcare | E19: 150 | F19: 0 | G19: =E19-F19 | H19: =IF(E19>0,F19/E19,0)
D20: Insurance | E20: 250 | F20: 0 | G20: =E20-F20 | H20: =IF(E20>0,F20/E20,0)
B21: MONTHLY | D21: Entertainment | E21: 150 | F21: 0 | G21: =E21-F21 | H21: =IF(E21>0,F21/E21,0)
B22: JANUARY | D22: Shopping | E22: 200 | F22: 0 | G22: =E22-F22 | H22: =IF(E22>0,F22/E22,0)
B23: FEBRUARY | D23: Personal Care | E23: 100 | F23: 0 | G23: =E23-F23 | H23: =IF(E23>0,F23/E23,0)
B24: MARCH | D24: Education | E24: 50 | F24: 0 | G24: =E24-F24 | H24: =IF(E24>0,F24/E24,0)
B25: APRIL | D25: Savings | E25: 500 | F25: 0 | G25: =E25-F25 | H25: =IF(E25>0,F25/E25,0)
B26: MAY | D26: Investments | E26: 300 | F26: 0 | G26: =E26-F26 | H26: =IF(E26>0,F26/E26,0)
B27: JUNE | D27: Debt Payments | E27: 200 | F27: 0 | G27: =E27-F27 | H27: =IF(E27>0,F27/E27,0)
B28: JULY | D28: Gifts & Donations | E28: 100 | F28: 0 | G28: =E28-F28 | H28: =IF(E28>0,F28/E28,0)
B29: AUGUST | D29: Other | E29: 100 | F29: 0 | G29: =E29-F29 | H29: =IF(E29>0,F29/E29,0)
B30: SEPTEMBER | D30: TOTAL EXPENSES | E30: =SUM(E15:E29) | F30: =SUM(F15:F29) | G30: =SUM(G15:G29)
B31: OCTOBER
B32: NOVEMBER | D32: MONTHLY SUMMARY
B33: DECEMBER | D33: Net Savings (Actual Income − Actual Expenses) | G33: =F11-F30
B35: TOOLS
B36: 50-30-20
B37: EXPENSE DIST
B38: SINKING FUNDS
B39: DEBT CALC
B40: NET WORTH
B41: INVEST FORECAST
B42: NO-SPEND

Sheet AUGUST
B2: PLANWISE HAUS | D2: PLANWISE HAUS · AUGUST
D3: EXCEL TEMPLATES FOR LIFE & HOME
B5: OVERVIEW | D5: INCOME — AUGUST 2025
B6: INSTRUCTIONS | D6: Source | E6: Budgeted | F6: Actual | G6: Difference | H6: Notes
B7: SETUP | D7: Primary Salary | E7: 5000 | F7: 5000 | G7: =F7-E7
B8: DASHBOARD | D8: Side Income | E8: 500 | F8: 0 | G8: =F8-E8
D9: Other | E9: 0 | F9: 0 | G9: =F9-E9
B10: ACCOUNTS
B11: BANK ACCOUNTS | D11: TOTAL INCOME | E11: =SUM(E7:E10) | F11: =SUM(F7:F10)
B12: RECURRING
B13: PAYMENTS | D13: EXPENSES — AUGUST 2025
B14: VARIABLE | D14: Category | E14: Budget | F14: Actual Spent | G14: Remaining | H14: % Used | I14: Notes
D15: Housing | E15: 1500 | F15: 0 | G15: =E15-F15 | H15: =IF(E15>0,F15/E15,0)
B16: ANALYTICS | D16: Transportation | E16: 400 | F16: 0 | G16: =E16-F16 | H16: =IF(E16>0,F16/E16,0)
B17: ANNUAL TOTALS | D17: Food & Dining | E17: 600 | F17: 0 | G17: =E17-F17 | H17: =IF(E17>0,F17/E17,0)
B18: PAYCHECK | D18: Utilities | E18: 200 | F18: 0 | G18: =E18-F18 | H18: =IF(E18>0,F18/E18,0)
B19: CALENDAR | D19: Healthcare | E19: 150 | F19: 0 | G19: =E19-F19 | H19: =IF(E19>0,F19/E19,0)
D20: Insurance | E20: 250 | F20: 0 | G20: =E20-F20 | H20: =IF(E20>0,F20/E20,0)
B21: MONTHLY | D21: Entertainment | E21: 150 | F21: 0 | G21: =E21-F21 | H21: =IF(E21>0,F21/E21,0)
B22: JANUARY | D22: Shopping | E22: 200 | F22: 0 | G22: =E22-F22 | H22: =IF(E22>0,F22/E22,0)
B23: FEBRUARY | D23: Personal Care | E23: 100 | F23: 0 | G23: =E23-F23 | H23: =IF(E23>0,F23/E23,0)
B24: MARCH | D24: Education | E24: 50 | F24: 0 | G24: =E24-F24 | H24: =IF(E24>0,F24/E24,0)
B25: APRIL | D25: Savings | E25: 500 | F25: 0 | G25: =E25-F25 | H25: =IF(E25>0,F25/E25,0)
B26: MAY | D26: Investments | E26: 300 | F26: 0 | G26: =E26-F26 | H26: =IF(E26>0,F26/E26,0)
B27: JUNE | D27: Debt Payments | E27: 200 | F27: 0 | G27: =E27-F27 | H27: =IF(E27>0,F27/E27,0)
B28: JULY | D28: Gifts & Donations | E28: 100 | F28: 0 | G28: =E28-F28 | H28: =IF(E28>0,F28/E28,0)
B29: AUGUST | D29: Other | E29: 100 | F29: 0 | G29: =E29-F29 | H29: =IF(E29>0,F29/E29,0)
B30: SEPTEMBER | D30: TOTAL EXPENSES | E30: =SUM(E15:E29) | F30: =SUM(F15:F29) | G30: =SUM(G15:G29)
B31: OCTOBER
B32: NOVEMBER | D32: MONTHLY SUMMARY
B33: DECEMBER | D33: Net Savings (Actual Income − Actual Expenses) | G33: =F11-F30
B35: TOOLS
B36: 50-30-20
B37: EXPENSE DIST
B38: SINKING FUNDS
B39: DEBT CALC
B40: NET WORTH
B41: INVEST FORECAST
B42: NO-SPEND

Sheet SEPTEMBER
B2: PLANWISE HAUS | D2: PLANWISE HAUS · SEPTEMBER
D3: EXCEL TEMPLATES FOR LIFE & HOME
B5: OVERVIEW | D5: INCOME — SEPTEMBER 2025
B6: INSTRUCTIONS | D6: Source | E6: Budgeted | F6: Actual | G6: Difference | H6: Notes
B7: SETUP | D7: Primary Salary | E7: 5000 | F7: 5000 | G7: =F7-E7
B8: DASHBOARD | D8: Side Income | E8: 500 | F8: 0 | G8: =F8-E8
D9: Other | E9: 0 | F9: 0 | G9: =F9-E9
B10: ACCOUNTS
B11: BANK ACCOUNTS | D11: TOTAL INCOME | E11: =SUM(E7:E10) | F11: =SUM(F7:F10)
B12: RECURRING
B13: PAYMENTS | D13: EXPENSES — SEPTEMBER 2025
B14: VARIABLE | D14: Category | E14: Budget | F14: Actual Spent | G14: Remaining | H14: % Used | I14: Notes
D15: Housing | E15: 1500 | F15: 0 | G15: =E15-F15 | H15: =IF(E15>0,F15/E15,0)
B16: ANALYTICS | D16: Transportation | E16: 400 | F16: 0 | G16: =E16-F16 | H16: =IF(E16>0,F16/E16,0)
B17: ANNUAL TOTALS | D17: Food & Dining | E17: 600 | F17: 0 | G17: =E17-F17 | H17: =IF(E17>0,F17/E17,0)
B18: PAYCHECK | D18: Utilities | E18: 200 | F18: 0 | G18: =E18-F18 | H18: =IF(E18>0,F18/E18,0)
B19: CALENDAR | D19: Healthcare | E19: 150 | F19: 0 | G19: =E19-F19 | H19: =IF(E19>0,F19/E19,0)
D20: Insurance | E20: 250 | F20: 0 | G20: =E20-F20 | H20: =IF(E20>0,F20/E20,0)
B21: MONTHLY | D21: Entertainment | E21: 150 | F21: 0 | G21: =E21-F21 | H21: =IF(E21>0,F21/E21,0)
B22: JANUARY | D22: Shopping | E22: 200 | F22: 0 | G22: =E22-F22 | H22: =IF(E22>0,F22/E22,0)
B23: FEBRUARY | D23: Personal Care | E23: 100 | F23: 0 | G23: =E23-F23 | H23: =IF(E23>0,F23/E23,0)
B24: MARCH | D24: Education | E24: 50 | F24: 0 | G24: =E24-F24 | H24: =IF(E24>0,F24/E24,0)
B25: APRIL | D25: Savings | E25: 500 | F25: 0 | G25: =E25-F25 | H25: =IF(E25>0,F25/E25,0)
B26: MAY | D26: Investments | E26: 300 | F26: 0 | G26: =E26-F26 | H26: =IF(E26>0,F26/E26,0)
B27: JUNE | D27: Debt Payments | E27: 200 | F27: 0 | G27: =E27-F27 | H27: =IF(E27>0,F27/E27,0)
B28: JULY | D28: Gifts & Donations | E28: 100 | F28: 0 | G28: =E28-F28 | H28: =IF(E28>0,F28/E28,0)
B29: AUGUST | D29: Other | E29: 100 | F29: 0 | G29: =E29-F29 | H29: =IF(E29>0,F29/E29,0)
B30: SEPTEMBER | D30: TOTAL EXPENSES | E30: =SUM(E15:E29) | F30: =SUM(F15:F29) | G30: =SUM(G15:G29)
B31: OCTOBER
B32: NOVEMBER | D32: MONTHLY SUMMARY
B33: DECEMBER | D33: Net Savings (Actual Income − Actual Expenses) | G33: =F11-F30
B35: TOOLS
B36: 50-30-20
B37: EXPENSE DIST
B38: SINKING FUNDS
B39: DEBT CALC
B40: NET WORTH
B41: INVEST FORECAST
B42: NO-SPEND

Sheet OCTOBER
B2: PLANWISE HAUS | D2: PLANWISE HAUS · OCTOBER
D3: EXCEL TEMPLATES FOR LIFE & HOME
B5: OVERVIEW | D5: INCOME — OCTOBER 2025
B6: INSTRUCTIONS | D6: Source | E6: Budgeted | F6: Actual | G6: Difference | H6: Notes
B7: SETUP | D7: Primary Salary | E7: 5000 | F7: 5000 | G7: =F7-E7
B8: DASHBOARD | D8: Side Income | E8: 500 | F8: 0 | G8: =F8-E8
D9: Other | E9: 0 | F9: 0 | G9: =F9-E9
B10: ACCOUNTS
B11: BANK ACCOUNTS | D11: TOTAL INCOME | E11: =SUM(E7:E10) | F11: =SUM(F7:F10)
B12: RECURRING
B13: PAYMENTS | D13: EXPENSES — OCTOBER 2025
B14: VARIABLE | D14: Category | E14: Budget | F14: Actual Spent | G14: Remaining | H14: % Used | I14: Notes
D15: Housing | E15: 1500 | F15: 0 | G15: =E15-F15 | H15: =IF(E15>0,F15/E15,0)
B16: ANALYTICS | D16: Transportation | E16: 400 | F16: 0 | G16: =E16-F16 | H16: =IF(E16>0,F16/E16,0)
B17: ANNUAL TOTALS | D17: Food & Dining | E17: 600 | F17: 0 | G17: =E17-F17 | H17: =IF(E17>0,F17/E17,0)
B18: PAYCHECK | D18: Utilities | E18: 200 | F18: 0 | G18: =E18-F18 | H18: =IF(E18>0,F18/E18,0)
B19: CALENDAR | D19: Healthcare | E19: 150 | F19: 0 | G19: =E19-F19 | H19: =IF(E19>0,F19/E19,0)
D20: Insurance | E20: 250 | F20: 0 | G20: =E20-F20 | H20: =IF(E20>0,F20/E20,0)
B21: MONTHLY | D21: Entertainment | E21: 150 | F21: 0 | G21: =E21-F21 | H21: =IF(E21>0,F21/E21,0)
B22: JANUARY | D22: Shopping | E22: 200 | F22: 0 | G22: =E22-F22 | H22: =IF(E22>0,F22/E22,0)
B23: FEBRUARY | D23: Personal Care | E23: 100 | F23: 0 | G23: =E23-F23 | H23: =IF(E23>0,F23/E23,0)
B24: MARCH | D24: Education | E24: 50 | F24: 0 | G24: =E24-F24 | H24: =IF(E24>0,F24/E24,0)
B25: APRIL | D25: Savings | E25: 500 | F25: 0 | G25: =E25-F25 | H25: =IF(E25>0,F25/E25,0)
B26: MAY | D26: Investments | E26: 300 | F26: 0 | G26: =E26-F26 | H26: =IF(E26>0,F26/E26,0)
B27: JUNE | D27: Debt Payments | E27: 200 | F27: 0 | G27: =E27-F27 | H27: =IF(E27>0,F27/E27,0)
B28: JULY | D28: Gifts & Donations | E28: 100 | F28: 0 | G28: =E28-F28 | H28: =IF(E28>0,F28/E28,0)
B29: AUGUST | D29: Other | E29: 100 | F29: 0 | G29: =E29-F29 | H29: =IF(E29>0,F29/E29,0)
B30: SEPTEMBER | D30: TOTAL EXPENSES | E30: =SUM(E15:E29) | F30: =SUM(F15:F29) | G30: =SUM(G15:G29)
B31: OCTOBER
B32: NOVEMBER | D32: MONTHLY SUMMARY
B33: DECEMBER | D33: Net Savings (Actual Income − Actual Expenses) | G33: =F11-F30
B35: TOOLS
B36: 50-30-20
B37: EXPENSE DIST
B38: SINKING FUNDS
B39: DEBT CALC
B40: NET WORTH
B41: INVEST FORECAST
B42: NO-SPEND

Sheet NOVEMBER
B2: PLANWISE HAUS | D2: PLANWISE HAUS · NOVEMBER
D3: EXCEL TEMPLATES FOR LIFE & HOME
B5: OVERVIEW | D5: INCOME — NOVEMBER 2025
B6: INSTRUCTIONS | D6: Source | E6: Budgeted | F6: Actual | G6: Difference | H6: Notes
B7: SETUP | D7: Primary Salary | E7: 5000 | F7: 5000 | G7: =F7-E7
B8: DASHBOARD | D8: Side Income | E8: 500 | F8: 0 | G8: =F8-E8
D9: Other | E9: 0 | F9: 0 | G9: =F9-E9
B10: ACCOUNTS
B11: BANK ACCOUNTS | D11: TOTAL INCOME | E11: =SUM(E7:E10) | F11: =SUM(F7:F10)
B12: RECURRING
B13: PAYMENTS | D13: EXPENSES — NOVEMBER 2025
B14: VARIABLE | D14: Category | E14: Budget | F14: Actual Spent | G14: Remaining | H14: % Used | I14: Notes
D15: Housing | E15: 1500 | F15: 0 | G15: =E15-F15 | H15: =IF(E15>0,F15/E15,0)
B16: ANALYTICS | D16: Transportation | E16: 400 | F16: 0 | G16: =E16-F16 | H16: =IF(E16>0,F16/E16,0)
B17: ANNUAL TOTALS | D17: Food & Dining | E17: 600 | F17: 0 | G17: =E17-F17 | H17: =IF(E17>0,F17/E17,0)
B18: PAYCHECK | D18: Utilities | E18: 200 | F18: 0 | G18: =E18-F18 | H18: =IF(E18>0,F18/E18,0)
B19: CALENDAR | D19: Healthcare | E19: 150 | F19: 0 | G19: =E19-F19 | H19: =IF(E19>0,F19/E19,0)
D20: Insurance | E20: 250 | F20: 0 | G20: =E20-F20 | H20: =IF(E20>0,F20/E20,0)
B21: MONTHLY | D21: Entertainment | E21: 150 | F21: 0 | G21: =E21-F21 | H21: =IF(E21>0,F21/E21,0)
B22: JANUARY | D22: Shopping | E22: 200 | F22: 0 | G22: =E22-F22 | H22: =IF(E22>0,F22/E22,0)
B23: FEBRUARY | D23: Personal Care | E23: 100 | F23: 0 | G23: =E23-F23 | H23: =IF(E23>0,F23/E23,0)
B24: MARCH | D24: Education | E24: 50 | F24: 0 | G24: =E24-F24 | H24: =IF(E24>0,F24/E24,0)
B25: APRIL | D25: Savings | E25: 500 | F25: 0 | G25: =E25-F25 | H25: =IF(E25>0,F25/E25,0)
B26: MAY | D26: Investments | E26: 300 | F26: 0 | G26: =E26-F26 | H26: =IF(E26>0,F26/E26,0)
B27: JUNE | D27: Debt Payments | E27: 200 | F27: 0 | G27: =E27-F27 | H27: =IF(E27>0,F27/E27,0)
B28: JULY | D28: Gifts & Donations | E28: 100 | F28: 0 | G28: =E28-F28 | H28: =IF(E28>0,F28/E28,0)
B29: AUGUST | D29: Other | E29: 100 | F29: 0 | G29: =E29-F29 | H29: =IF(E29>0,F29/E29,0)
B30: SEPTEMBER | D30: TOTAL EXPENSES | E30: =SUM(E15:E29) | F30: =SUM(F15:F29) | G30: =SUM(G15:G29)
B31: OCTOBER
B32: NOVEMBER | D32: MONTHLY SUMMARY
B33: DECEMBER | D33: Net Savings (Actual Income − Actual Expenses) | G33: =F11-F30
B35: TOOLS
B36: 50-30-20
B37: EXPENSE DIST
B38: SINKING FUNDS
B39: DEBT CALC
B40: NET WORTH
B41: INVEST FORECAST
B42: NO-SPEND

Sheet DECEMBER
B2: PLANWISE HAUS | D2: PLANWISE HAUS · DECEMBER
D3: EXCEL TEMPLATES FOR LIFE & HOME
B5: OVERVIEW | D5: INCOME — DECEMBER 2025
B6: INSTRUCTIONS | D6: Source | E6: Budgeted | F6: Actual | G6: Difference | H6: Notes
B7: SETUP | D7: Primary Salary | E7: 5000 | F7: 5000 | G7: =F7-E7
B8: DASHBOARD | D8: Side Income | E8: 500 | F8: 0 | G8: =F8-E8
D9: Other | E9: 0 | F9: 0 | G9: =F9-E9
B10: ACCOUNTS
B11: BANK ACCOUNTS | D11: TOTAL INCOME | E11: =SUM(E7:E10) | F11: =SUM(F7:F10)
B12: RECURRING
B13: PAYMENTS | D13: EXPENSES — DECEMBER 2025
B14: VARIABLE | D14: Category | E14: Budget | F14: Actual Spent | G14: Remaining | H14: % Used | I14: Notes
D15: Housing | E15: 1500 | F15: 0 | G15: =E15-F15 | H15: =IF(E15>0,F15/E15,0)
B16: ANALYTICS | D16: Transportation | E16: 400 | F16: 0 | G16: =E16-F16 | H16: =IF(E16>0,F16/E16,0)
B17: ANNUAL TOTALS | D17: Food & Dining | E17: 600 | F17: 0 | G17: =E17-F17 | H17: =IF(E17>0,F17/E17,0)
B18: PAYCHECK | D18: Utilities | E18: 200 | F18: 0 | G18: =E18-F18 | H18: =IF(E18>0,F18/E18,0)
B19: CALENDAR | D19: Healthcare | E19: 150 | F19: 0 | G19: =E19-F19 | H19: =IF(E19>0,F19/E19,0)
D20: Insurance | E20: 250 | F20: 0 | G20: =E20-F20 | H20: =IF(E20>0,F20/E20,0)
B21: MONTHLY | D21: Entertainment | E21: 150 | F21: 0 | G21: =E21-F21 | H21: =IF(E21>0,F21/E21,0)
B22: JANUARY | D22: Shopping | E22: 200 | F22: 0 | G22: =E22-F22 | H22: =IF(E22>0,F22/E22,0)
B23: FEBRUARY | D23: Personal Care | E23: 100 | F23: 0 | G23: =E23-F23 | H23: =IF(E23>0,F23/E23,0)
B24: MARCH | D24: Education | E24: 50 | F24: 0 | G24: =E24-F24 | H24: =IF(E24>0,F24/E24,0)
B25: APRIL | D25: Savings | E25: 500 | F25: 0 | G25: =E25-F25 | H25: =IF(E25>0,F25/E25,0)
B26: MAY | D26: Investments | E26: 300 | F26: 0 | G26: =E26-F26 | H26: =IF(E26>0,F26/E26,0)
B27: JUNE | D27: Debt Payments | E27: 200 | F27: 0 | G27: =E27-F27 | H27: =IF(E27>0,F27/E27,0)
B28: JULY | D28: Gifts & Donations | E28: 100 | F28: 0 | G28: =E28-F28 | H28: =IF(E28>0,F28/E28,0)
B29: AUGUST | D29: Other | E29: 100 | F29: 0 | G29: =E29-F29 | H29: =IF(E29>0,F29/E29,0)
B30: SEPTEMBER | D30: TOTAL EXPENSES | E30: =SUM(E15:E29) | F30: =SUM(F15:F29) | G30: =SUM(G15:G29)
B31: OCTOBER
B32: NOVEMBER | D32: MONTHLY SUMMARY
B33: DECEMBER | D33: Net Savings (Actual Income − Actual Expenses) | G33: =F11-F30
B35: TOOLS
B36: 50-30-20
B37: EXPENSE DIST
B38: SINKING FUNDS
B39: DEBT CALC
B40: NET WORTH
B41: INVEST FORECAST
B42: NO-SPEND

Sheet 50-30-20
B2: PLANWISE HAUS | D2: PLANWISE HAUS · 50/30/20 BUDGET DASHBOARD
D3: EXCEL TEMPLATES FOR LIFE & HOME
B5: OVERVIEW | D5: THE 50/30/20 BUDGET RULE
B6: INSTRUCTIONS | D6: Monthly Net Income (from Setup) | G6: =SETUP!F31
B7: SETUP
B8: DASHBOARD | D8: Category | E8: Rule % | F8: Target Amount | G8: Actual (Annual Totals) | H8: Status
D9: NEEDS — Housing, Transport, Utilities, Healthcare, Insurance | E9: 0.5 | F9: =G6*0.50 | G9: =('ANNUAL TOTALS'!Q23+'ANNUAL TOTALS'!Q24+'ANNUAL TOTALS'!Q26+'ANNUAL TOTALS'!Q25+'ANNUAL TOTALS'!Q27)/12 | H9: =IF(H9<=F9,"On Track ✓","Over Budget ✗")
B10: ACCOUNTS | D10: WANTS — Entertainment, Shopping, Food & Dining, Personal Care | E10: 0.3 | F10: =G6*0.30 | G10: =('ANNUAL TOTALS'!Q25+'ANNUAL TOTALS'!Q30+'ANNUAL TOTALS'!Q29+'ANNUAL TOTALS'!Q31)/12 | H10: =IF(H10<=F10,"On Track ✓","Over Budget ✗")
B11: BANK ACCOUNTS | D11: SAVINGS & DEBT — Savings, Investments, Debt Payments | E11: 0.2 | F11: =G6*0.20 | G11: =('ANNUAL TOTALS'!Q33+'ANNUAL TOTALS'!Q34+'ANNUAL TOTALS'!Q35)/12 | H11: =IF(H11<=F11,"On Track ✓","Over Budget ✗")
B12: RECURRING | D12: HOW THE 50/30/20 RULE WORKS
B13: PAYMENTS | D13: 50% NEEDS | E13: Essentials you must pay — rent, groceries, utilities, insurance, minimum debt payments.
B14: VARIABLE | D14: 30% WANTS | E14: Non-essentials that improve quality of life — dining out, streaming, hobbies, travel.
D15: 20% SAVINGS | E15: Savings, investments, and extra debt repayment to build long-term wealth.
B16: ANALYTICS
B17: ANNUAL TOTALS
B18: PAYCHECK
B19: CALENDAR
B21: MONTHLY
B22: JANUARY
B23: FEBRUARY
B24: MARCH
B25: APRIL
B26: MAY
B27: JUNE
B28: JULY
... B42: NO-SPEND

Sheet EXPENSE DIST
B2: PLANWISE HAUS | D2: PLANWISE HAUS · EXPENSE DISTRIBUTION
D3: EXCEL TEMPLATES FOR LIFE & HOME
B5: OVERVIEW | D5: ANNUAL EXPENSE DISTRIBUTION BY CATEGORY
B6: INSTRUCTIONS | D6: Category | E6: Annual Budget | F6: Annual Actual | G6: % of Total
B7: SETUP | D7: Housing | E7: 18000 | F7: ='ANNUAL TOTALS'!Q23 | G7: =IF(SUM(F7:F21)>0,F7/SUM(F7:F21),0)
B8: DASHBOARD | D8: Transportation | E8: 4800 | F8: ='ANNUAL TOTALS'!Q24 | G8: =IF(SUM(F7:F21)>0,F8/SUM(F7:F21),0)
D9: Food & Dining | E9: 7200 | F9: ='ANNUAL TOTALS'!Q25 | G9: =IF(SUM(F7:F21)>0,F9/SUM(F7:F21),0)
B10: ACCOUNTS | D10: Utilities | E10: 2400 | F10: ='ANNUAL TOTALS'!Q26 | G10: =IF(SUM(F7:F21)>0,F10/SUM(F7:F21),0)
B11: BANK ACCOUNTS | D11: Healthcare | E11: 1800 | F11: ='ANNUAL TOTALS'!Q27 | G11: =IF(SUM(F7:F21)>0,F11/SUM(F7:F21),0)
B12: RECURRING | D12: Insurance | E12: 3000 | F12: ='ANNUAL TOTALS'!Q28 | G12: =IF(SUM(F7:F21)>0,F12/SUM(F7:F21),0)
B13: PAYMENTS | D13: Entertainment | E13: 1800 | F13: ='ANNUAL TOTALS'!Q29 | G13: =IF(SUM(F7:F21)>0,F13/SUM(F7:F21),0)
B14: VARIABLE | D14: Shopping | E14: 2400 | F14: ='ANNUAL TOTALS'!Q30 | G14: =IF(SUM(F7:F21)>0,F14/SUM(F7:F21),0)
D15: Personal Care | E15: 1200 | F15: ='ANNUAL TOTALS'!Q31 | G15: =IF(SUM(F7:F21)>0,F15/SUM(F7:F21),0)
B16: ANALYTICS | D16: Education | E16: 600 | F16: ='ANNUAL TOTALS'!Q32 | G16: =IF(SUM(F7:F21)>0,F16/SUM(F7:F21),0)
B17: ANNUAL TOTALS | D17: Savings | E17: 6000 | F17: ='ANNUAL TOTALS'!Q33 | G17: =IF(SUM(F7:F21)>0,F17/SUM(F7:F21),0)
B18: PAYCHECK | D18: Investments | E18: 3600 | F18: ='ANNUAL TOTALS'!Q34 | G18: =IF(SUM(F7:F21)>0,F18/SUM(F7:F21),0)
B19: CALENDAR | D19: Debt Payments | E19: 2400 | F19: ='ANNUAL TOTALS'!Q35 | G19: =IF(SUM(F7:F21)>0,F19/SUM(F7:F21),0)
D20: Gifts & Donations | E20: 1200 | F20: ='ANNUAL TOTALS'!Q36 | G20: =IF(SUM(F7:F21)>0,F20/SUM(F7:F21),0)
B21: MONTHLY | D21: Other | E21: 1200 | F21: ='ANNUAL TOTALS'!Q37 | G21: =IF(SUM(F7:F21)>0,F21/SUM(F7:F21),0)
B22: JANUARY | D22: TOTAL | E22: =SUM(E7:E21) | F22: =SUM(F7:F21)
B23: FEBRUARY
B24: MARCH
B25: APRIL
B26: MAY
B27: JUNE
B28: JULY
B29: AUGUST
B30: SEPTEMBER
B31: OCTOBER
B32: NOVEMBER
B33: DECEMBER
B35: TOOLS
... B42: NO-SPEND

Sheet SINKING FUNDS
B2: PLANWISE HAUS | D2: PLANWISE HAUS · SINKING FUNDS TRACKER
D3: EXCEL TEMPLATES FOR LIFE & HOME
B5: OVERVIEW | D5: SINKING FUNDS TRACKER
B6: INSTRUCTIONS | D6: Fund Name | E6: Goal Amount | F6: Current Balance | G6: Monthly Contribution | H6: Months Left | I6: % Complete | J6: Target Date
B7: SETUP | D7: Emergency Fund | E7: 10000 | F7: 4500 | G7: 500 | H7: =CEILING(MAX(0,(E7-F7)/G7),1) | I7: =MIN(1,F7/E7) | J7: 12/31/2025
B8: DASHBOARD | D8: Car Repair Fund | E8: 2000 | F8: 800 | G8: 150 | H8: =CEILING(MAX(0,(E8-F8)/G8),1) | I8: =MIN(1,F8/E8) | J8: 06/30/2025
D9: Vacation Fund | E9: 3000 | F9: 1200 | G9: 250 | H9: =CEILING(MAX(0,(E9-F9)/G9),1) | I9: =MIN(1,F9/E9) | J9: 08/01/2025
B10: ACCOUNTS | D10: Home Repair Fund | E10: 5000 | F10: 2000 | G10: 300 | H10: =CEILING(MAX(0,(E10-F10)/G10),1) | I10: =MIN(1,F10/E10) | J10: 12/31/2025
B11: BANK ACCOUNTS | D11: Holiday Gifts | E11: 1500 | F11: 500 | G11: 100 | H11: =CEILING(MAX(0,(E11-F11)/G11),1) | I11: =MIN(1,F11/E11) | J11: 11/30/2025
B12: RECURRING | D12: New Laptop | E12: 2000 | F12: 600 | G12: 200 | H12: =CEILING(MAX(0,(E12-F12)/G12),1) | I12: =MIN(1,F12/E12) | J12: 09/01/2025
B13: PAYMENTS
B14: VARIABLE
B16: ANALYTICS
B17: ANNUAL TOTALS
B18: PAYCHECK
B19: CALENDAR
B21: MONTHLY
B22: JANUARY
B23: FEBRUARY
B24: MARCH
B25: APRIL
B26: MAY
... B42: NO-SPEND

Sheet DEBT CALC
B2: PLANWISE HAUS | D2: PLANWISE HAUS · DEBT PAYOFF CALCULATOR
D3: EXCEL TEMPLATES FOR LIFE & HOME
B5: OVERVIEW | D5: DEBT PAYOFF CALCULATOR
B6: INSTRUCTIONS | D6: Debt Name | E6: Current Balance | F6: Interest Rate (APR) | G6: Min Payment | H6: Extra Payment | I6: Payoff Date (Est.) | J6: Total Interest
B7: SETUP | D7: Credit Card A | E7: 3500 | F7: 0.2199 | G7: 70 | H7: 100 | I7: =EDATE(TODAY(),=IF(F7=0,CEILING(E7/(=G7+H7),1),CEILING(NPER(=F7/12,-(=G7+H7),E7),1))) | J7: =IF(F7=0,0,MAX(0,(=G7+H7)*=IF(F7=0,CEILING(E7/(=G7+H7),1),CEILING(NPER(=F7/12,-(=G7+H7),E7),1))-E7))
B8: DASHBOARD | D8: Credit Card B | E8: 1200 | F8: 0.1799 | G8: 25 | H8: 50 | I8: =EDATE(TODAY(),=IF(F8=0,CEILING(E8/(=G8+H8),1),CEILING(NPER(=F8/12,-(=G8+H8),E8),1))) | J8: =IF(F8=0,0,MAX(0,(=G8+H8)*=IF(F8=0,CEILING(E8/(=G8+H8),1),CEILING(NPER(=F8/12,-(=G8+H8),E8),1))-E8))
D9: Student Loan | E9: 15000 | F9: 0.0675 | G9: 150 | H9: 200 | I9: =EDATE(TODAY(),=IF(F9=0,CEILING(E9/(=G9+H9),1),CEILING(NPER(=F9/12,-(=G9+H9),E9),1))) | J9: =IF(F9=0,0,MAX(0,(=G9+H9)*=IF(F9=0,CEILING(E9/(=G9+H9),1),CEILING(NPER(=F9/12,-(=G9+H9),E9),1))-E9))
B10: ACCOUNTS | D10: Car Loan | E10: 12000 | F10: 0.0499 | G10: 385 | H10: 0 | I10: =EDATE(TODAY(),=IF(F10=0,CEILING(E10/(=G10+H10),1),CEILING(NPER(=F10/12,-(=G10+H10),E10),1))) | J10: =IF(F10=0,0,MAX(0,(=G10+H10)*=IF(F10=0,CEILING(E10/(=G10+H10),1),CEILING(NPER(=F10/12,-(=G10+H10),E10),1))-E10))
B11: BANK ACCOUNTS | D11: Medical Bill | E11: 800 | F11: 0 | G11: 100 | H11: 100 | I11: =EDATE(TODAY(),=IF(F11=0,CEILING(E11/(=G11+H11),1),CEILING(NPER(=F11/12,-(=G11+H11),E11),1))) | J11: =IF(F11=0,0,MAX(0,(=G11+H11)*=IF(F11=0,CEILING(E11/(=G11+H11),1),CEILING(NPER(=F11/12,-(=G11+H11),E11),1))-E11))
B12: RECURRING
B13: PAYMENTS | D13: TOTALS | E13: =SUM(E7:E12) | G13: =SUM(G7:G12) | H13: =SUM(H7:H12) | J13: =SUM(J7:J12)
B14: VARIABLE
B16: ANALYTICS
B17: ANNUAL TOTALS
B18: PAYCHECK
B19: CALENDAR
B21: MONTHLY
B22: JANUARY
B23: FEBRUARY
B24: MARCH
B25: APRIL
B26: MAY
B27: JUNE
... B42: NO-SPEND

Sheet NET WORTH
B2: PLANWISE HAUS | D2: PLANWISE HAUS · NET WORTH TRACKER
D3: EXCEL TEMPLATES FOR LIFE & HOME
B5: OVERVIEW | D5: ASSETS
B6: INSTRUCTIONS | D6: Asset | E6: Opening Value | F6: Current Value | G6: Change
B7: SETUP | D7: Checking Account | E7: 3500 | F7: 4250 | G7: =F7-E7
B8: DASHBOARD | D8: Emergency Savings | E8: 10000 | F8: 10500 | G8: =F8-E8
D9: Investment Portfolio | E9: 25000 | F9: 26800 | G9: =F9-E9
B10: ACCOUNTS | D10: 401(k) / Retirement | E10: 45000 | F10: 47500 | G10: =F10-E10
B11: BANK ACCOUNTS | D11: Home Value | E11: 350000 | F11: 355000 | G11: =F11-E11
B12: RECURRING | D12: Vehicle Value | E12: 18000 | F12: 16500 | G12: =F12-E12
B13: PAYMENTS | D13: Other Assets | E13: 5000 | F13: 5000 | G13: =F13-E13
B14: VARIABLE
D15: TOTAL ASSETS | F15: =SUM(F7:F14)
B16: ANALYTICS
B17: ANNUAL TOTALS | D17: LIABILITIES
B18: PAYCHECK | D18: Liability | E18: Opening Balance | F18: Current Balance | G18: Change
B19: CALENDAR | D19: Mortgage | E19: 280000 | F19: 279200 | G19: =F19-E19
D20: Car Loan | E20: 12000 | F20: 11200 | G20: =F20-E20
B21: MONTHLY | D21: Student Loans | E21: 15000 | F21: 14500 | G21: =F21-E21
B22: JANUARY | D22: Credit Card Debt | E22: 3500 | F22: 2800 | G22: =F22-E22
B23: FEBRUARY | D23: Other Debt | E23: 0 | F23: 0 | G23: =F23-E23
B24: MARCH
B25: APRIL | D25: TOTAL LIABILITIES | F25: =SUM(F19:F24)
B26: MAY
B27: JUNE | D27: NET WORTH
B28: JULY | D28: NET WORTH (Assets − Liabilities) | F28: =F15-F25
B29: AUGUST
B30: SEPTEMBER
B31: OCTOBER
B32: NOVEMBER
B33: DECEMBER
B35: TOOLS
B36: 50-30-20
B37: EXPENSE DIST
B38: SINKING FUNDS
B39: DEBT CALC
B40: NET WORTH
B41: INVEST FORECAST
B42: NO-SPEND

Sheet INVEST FORECAST
B2: PLANWISE HAUS | D2: PLANWISE HAUS · INVESTMENT FORECAST
D3: EXCEL TEMPLATES FOR LIFE & HOME
B5: OVERVIEW | D5: COMPOUND GROWTH CALCULATOR
B6: INSTRUCTIONS | D6: Starting Investment | G6: 10000
